
# 1. Errors and Exceptions

* 발생할 수 있는 오류와 예외처리를 확인해봅시다.

## 1.1 문법 에러 (Syntax Error)

- 가장 많이 만날 수 있는 에러로 발생한 `파일 이름`과 `줄`, `^`을 통해 파이썬이 읽어 들일 때(parser)의 문제 발생 위치를 표현한다.
> `parser` 는 문제가 되는 줄을 다시 보여주고 줄에서 에러가 감지된 가장 앞의 위치를 가리키는 작은 '화살표'를 표시합니다.


```python
# if문을 통해 발생시켜봅시다.
```


```python
if True:
    print('참')
else
    print('거짓')
```


```python
# print문을 통해 다른 오류를 발생시켜봅시다.
# EOL 오류(따옴표 오류) 를 봅시다
```


```python
print('hi)
```


```python
# EOF 에러(괄호 닫기 오류)도 보게 됩니다.
```


```python
print('hi'
```


```python
# 정확한 위치를 지정하지 않을 수도 있으므로 앞뒤로 모두 확인을 해봐야합니다.
```


```python
if True print('참')
```

## 1.2 예외 (Exceptions)

* 문법이나 표현식이 바르게 되어있지만, 실행시 발생하는 에러입니다.

* 아래 제시된 모든 에러는 Exception을 상속받아 이뤄집니다.


```python
# ZeroDivisionError를 확인해봅시다.
```


```python
10 * (1/0)
```


```python
# NameError를 확인해봅시다. 
```


```python
print(abc)
```


```python
# TypeError를 확인해봅시다.
```


```python
1 + '1'
```


```python
# 함수 호출과정에서 TypeError도 발생하게 됩니다. 확인해봅시다.
```


```python
round('3.5')
```


```python
# 함수호출 과정에서 다양한 오류를 확인할 수 있습니다. : 필수 argument 누락
```


```python
import random

random.sample([1, 2, 3])
```


```python
# 함수호출 과정에서 다양한 오류를 확인할 수 있습니다. : argument 많은 경우
```


```python
random.choice([1, 2, 3], 2)
```


```python
# ValueError를 확인해봅시다
```


```python
numbers = [1, 2]
number.index(3)
```


```python
# ValueError를 확인해봅시다.
```


```python
valueError: 3 is not in list
```


```python
# IndexError를 확인해봅시다.
```


```python
empy_list = []
empy_list[-1]
```


```python
# KeyError를 확인해봅시다. 
```


```python
songs = {'임창정': '소주한잔', '아이유': '좋은날'}

songs['박상민']
```


```python
# ModuleNotFoundError를 확인해봅시다.
```


```python
import reque
```


```python
# ImportError 확인해봅시다.
```


```python
from bs4 import Bs
```


```python
# KeyboardInterrupt를 확인해봅시다.
```


```python
vscode에서 ctrl + c 누르면 나옴
```

# 2. 예외 처리 

## 2.1 기본  - `try` `except`
`try` 구문을 이용하여 예외 처리를 할 수 있습니다.

기본은 다음과 같은 구조를 가지고 있습니다.

```python
try:
    codeblock1
except 예외:
    codeblock2
```

* `try`절이 실행됩니다. 

* 예외가 발생되지 않으면, `except`없이 실행이 종료 됩니다.

* 예외가 중간에 발생하면, **남은 부분을 수행하지 않고**, `except`가 실행됩니다.


```python
# 사용자로부터 값을 받아 정수로 변환하여 출력해봅시다.
```


```python
num = input('값을 입력하세요: ')
print(int(num))
```


```python
# 사용자가 문자열을 넣어 해당 오류(ValueError)가 발생하면, 숫자를 입력하라고 출력해봅시다.
```


```python
try:
    num = input('값을 입력하세요: ')
    print(int(num))
except ValueError:
    print('바보야 수자 입력해!')
```

## 2.1 복수의 예외 처리

* 하나 이상의 예외를 모두 처리할 수 있습니다. 
* 괄호가 있는 튜플로 여러 개의 예외를 지정할 수 있습니다.

```python
try:
    codeblock1
except (예외1, 예외2):
    codeblock2
```


```python
# 100을 사용자가 입력한 값으로 나눈 후 출력하는 코드를 작성해봅시다.
```


```python
num = input('100으로 나눌 값을 입력해주세요: ')
print(100/int(num))
```


```python
# 문자열일때와 0일때 모두 처리를 해봅시다.
# 사용자가 입력한 값이 문자일 때 -> ValueError
# 사용자가 입력한 값이 0일 때 -> ZeroDivisionError
```


```python
try:
    num = input('100으로 나눌 값을 입력하세요: ')
    print(100 / int(num))
except (ValueError, ZeroDivisionError):
    print('숫자를 입력해')
```

    100으로 나눌 값을 입력하세요: efewf
    숫자를 입력해
    


```python
# 각각 다른 오류를 출력할 수도 있습니다.
```


```python
try:
    num = input('값을 입력하세요: ')
    print(100 / int(num))
except ValueError:
    print('숫자를 넣으라고')
except ZeroDivisionError:
    print('0은 아니지..')
except:
    print('나도 잘 모르겠는데 에러야..')
```

    값을 입력하세요: 31
    3.225806451612903
    

- 여기서 중요한 내용은 **에러가 순차적으로 수행됨**으로, 가장 작은 범주부터 시작해야 합니다.
    - if / else 와 같은 맥락


```python
try:
    num = input('값을 입력: ')
    print(100 / int(num))
except Exception:
    print('모르겠는데 에러야...') #에러의 아버지가 먼저 나오니까 다 걸림
except ValueError:
    print('숫자를 입력해야지') #작은 범주부터 먼저 올려야함
```

    값을 입력: 하하
    모르겠는데 에러야...
    


```python
#맥락으로 보면 아래와 같다.

a = int(input('숫자입력: '))
if a >= 0:
    print('hihihihi')
elif a > -1:
    print('hoithoit')
```

    숫자입력: 0
    hihihihi
    

## 2.3 에러 문구 처리

* 에러 문구를 함께 넘겨줄 수 있습니다.

```python
try:
    codeblock1
except 예외 as err:
    codeblock2
```


```python
# 에러 메세지를 넘겨줄 수도 있습니다.
```


```python
try:
    empty_list = []
    print(empty_list[-1])
except IndexError as err:
    print(f'{err}, 오류가 발생했습니다.')
```

    list index out of range, 오류가 발생했습니다.
    

## `else`

* 에러가 발생하지 않는 경우 수행되는 문장은 `else`를 이용합니다.
* 모든 except 절 뒤에와야 합니다.
* try 절이 예외를 일으키지 않을 때 실행되어야만 하는 코드에 적절합니다.

```python
try:
    codeblock1
except 예외:
    codeblock2
else:
    codeblock3
```


```python
# else를 사용해봅시다.
```


```python
try:
    numbers = [1, 2, 3]
    number = numbers[2]
except IndexError:
    print('비상 오류발생')
else:
    print(number * 100)
```

    300
    

## `finally` 

* 반드시 수행해야하는 문장은 `finally`를 활용합니다.
* 즉, 모든 상황에 실행되어야만 하는 코드를 정의하는데 활용합니다.
* 예외의 발생 여부과 관계없이 try 문을 떠날 때 항상 실행됩니다.
* else와 마찬가지로 모든 except 절 뒤에 나와야합니다.

```python
try:
    codeblock1
except 예외:
    codeblock2
finally:
    codeblock3
```


```python
# finally를 사용해봅시다.
```


```python
try:
    languages = {'python': 'good', 'javascript': 'goodgood'}
    languages['java']
except KeyError as err:
    print(f'{err}는 딕셔너리의 없는 키입니다.')
finally:
    print(f'finally, I\'m gonna get it.')
```

    'java'는 딕셔너리의 없는 키입니다.
    finally, I'm gonna get it.
    

# 3. 예외 발생시키기

`raise`를 통해 예외를 강제로 발생시킬 수 있습니다.


```python
# raise를 사용해봅시다.
```


```python
raise ValueError('hi')
```


    ---------------------------------------------------------------------------

    ValueError                                Traceback (most recent call last)

    <ipython-input-27-7365820dd368> in <module>
    ----> 1 raise ValueError('hi')
    

    ValueError: hi


## 실습 문제 1

>양의 정수 두개를 받아 몫과 나머지로 출력하는 함수를 만들어보세요.

`def my_div(num1,num2)`

- num2 가 0 이여서 발생하는 오류인 경우 **에러메시지**를 출력해주세요.
 
 예) division by zero 오류가 발생하였습니다.
 
 
- 인자가 string 이여서 발생하는 경우는 **ValueError와 함께 '숫자를 넣어주세요'를 출력** 해주세요.
(실제로 이 경우에 발생하는 것은 `TypeError`입니다.)


- 정상적인 경우에는 결과를 return합니다.


```python
# 여기에 코드를 작성하세요.
def my_div(num1, num2):
    try:
        result = num1 / num2
    except ZeroDivisionError as err:
        print(f'{err} 오류가 발생하였습니다.')
    except:
        raise ValueError('숫자를 넣어주세요')
    else:
        return result
```


```python
# my_div(1, 0)
my_div('1', '5')
```


    ---------------------------------------------------------------------------

    AssertionError                            Traceback (most recent call last)

    <ipython-input-42-290035cbfbe3> in <module>
          1 # my_div(1, 0)
    ----> 2 my_div('1', '5')
    

    <ipython-input-38-7032e460a9fd> in my_div(num1, num2)
          1 def my_div(num1, num2):
    ----> 2     assert type(num1)==int and type(num2)==int, '문자를 입력하였습니다.'
          3     try:
          4         result = num1 / num2
          5     except ZeroDivisionError as err:
    

    AssertionError: 문자를 입력하였습니다.


# `assert`

`assert` 문은 예외를 발생시키는 다른 방법이다. 

보통 **상태를 검증하는데 사용**되며 무조건 `AssertionError`가 발생한다.

```python
assert Boolean expression, error message
```

위의 검증식이 거짓일 경우를 발생한다.

`raise`는 항상 예외를 발생시키고, `assert`는 지정한 예외(조건)가 발생한다는 점에서 다르다.

## 실습 문제 2

>양의 정수 두개를 받아 몫과 나머지로 출력하는 함수를 만들어보세요.

`def my_div(num1,num2)`

- assert를 활용하여, int가 아닌 경우 AssertionError를 발생시켜봅시다.


```python
# 여기에 코드를 작성하세요.
```


```python
def my_div(num1, num2):
    assert type(num1)==int and type(num2)==int, '문자를 입력하였습니다.'
    try:
        result = num1 / num2
    except ZeroDivisionError as err:
        print(f'{err} 오류가 발생하였습니다.')
    else:
        return result
```


```python
my_div('1', '2')
# my_div(1, 2)
```


    ---------------------------------------------------------------------------

    AssertionError                            Traceback (most recent call last)

    <ipython-input-40-f7a4acd92a7e> in <module>
    ----> 1 my_div('1', '2')
          2 # my_div(1, 2)
    

    <ipython-input-38-7032e460a9fd> in my_div(num1, num2)
          1 def my_div(num1, num2):
    ----> 2     assert type(num1)==int and type(num2)==int, '문자를 입력하였습니다.'
          3     try:
          4         result = num1 / num2
          5     except ZeroDivisionError as err:
    

    AssertionError: 문자를 입력하였습니다.

